WARNING 2025-08-01 10:08:17,964 log 5854 140624463560960 Forbidden: /api/platos/
ERROR 2025-08-01 10:08:19,201 log 5854 140624463560960 Internal Server Error: /main/
Traceback (most recent call last):
  File "/home/ubuntu/.local/lib/python3.13/site-packages/django/core/handlers/exception.py", line 55, in inner
    response = get_response(request)
  File "/home/ubuntu/.local/lib/python3.13/site-packages/django/core/handlers/base.py", line 197, in _get_response
    response = wrapped_callback(request, *callback_args, **callback_kwargs)
  File "/home/ubuntu/.local/lib/python3.13/site-packages/django/contrib/auth/decorators.py", line 59, in _view_wrapper
    return view_func(request, *args, **kwargs)
  File "/workspace/myapp/views.py", line 155, in main
    return render(request, 'main.html', {
        'dias_semana': dias_semana,
    ...<6 lines>...
        'grupos': grupos,
    })
  File "/home/ubuntu/.local/lib/python3.13/site-packages/django/shortcuts.py", line 25, in render
    content = loader.render_to_string(template_name, context, request, using=using)
  File "/home/ubuntu/.local/lib/python3.13/site-packages/django/template/loader.py", line 62, in render_to_string
    return template.render(context, request)
           ~~~~~~~~~~~~~~~^^^^^^^^^^^^^^^^^^
  File "/home/ubuntu/.local/lib/python3.13/site-packages/django/template/backends/django.py", line 107, in render
    return self.template.render(context)
           ~~~~~~~~~~~~~~~~~~~~^^^^^^^^^
  File "/home/ubuntu/.local/lib/python3.13/site-packages/django/template/base.py", line 171, in render
    return self._render(context)
           ~~~~~~~~~~~~^^^^^^^^^
  File "/home/ubuntu/.local/lib/python3.13/site-packages/django/test/utils.py", line 114, in instrumented_test_render
    return self.nodelist.render(context)
           ~~~~~~~~~~~~~~~~~~~~^^^^^^^^^
  File "/home/ubuntu/.local/lib/python3.13/site-packages/django/template/base.py", line 1016, in render
    return SafeString("".join([node.render_annotated(context) for node in self]))
                               ~~~~~~~~~~~~~~~~~~~~~^^^^^^^^^
  File "/home/ubuntu/.local/lib/python3.13/site-packages/django/template/base.py", line 977, in render_annotated
    return self.render(context)
           ~~~~~~~~~~~^^^^^^^^^
  File "/home/ubuntu/.local/lib/python3.13/site-packages/django/template/base.py", line 1075, in render
    output = self.filter_expression.resolve(context)
  File "/home/ubuntu/.local/lib/python3.13/site-packages/django/template/base.py", line 749, in resolve
    new_obj = func(obj, *arg_vals)
  File "/home/ubuntu/.local/lib/python3.13/site-packages/django/template/defaultfilters.py", line 632, in length
    return len(value)
  File "/home/ubuntu/.local/lib/python3.13/site-packages/django/db/models/query.py", line 366, in __len__
    self._fetch_all()
    ~~~~~~~~~~~~~~~^^
  File "/home/ubuntu/.local/lib/python3.13/site-packages/django/db/models/query.py", line 1945, in _fetch_all
    self._result_cache = list(self._iterable_class(self))
                         ~~~~^^^^^^^^^^^^^^^^^^^^^^^^^^^^
  File "/home/ubuntu/.local/lib/python3.13/site-packages/django/db/models/query.py", line 91, in __iter__
    results = compiler.execute_sql(
        chunked_fetch=self.chunked_fetch, chunk_size=self.chunk_size
    )
  File "/home/ubuntu/.local/lib/python3.13/site-packages/django/db/models/sql/compiler.py", line 1610, in execute_sql
    sql, params = self.as_sql()
                  ~~~~~~~~~~~^^
  File "/home/ubuntu/.local/lib/python3.13/site-packages/django/db/models/sql/compiler.py", line 766, in as_sql
    extra_select, order_by, group_by = self.pre_sql_setup(
                                       ~~~~~~~~~~~~~~~~~~^
        with_col_aliases=with_col_aliases or bool(combinator),
        ^^^^^^^^^^^^^^^^^^^^^^^^^^^^^^^^^^^^^^^^^^^^^^^^^^^^^^
    )
    ^
  File "/home/ubuntu/.local/lib/python3.13/site-packages/django/db/models/sql/compiler.py", line 85, in pre_sql_setup
    self.setup_query(with_col_aliases=with_col_aliases)
    ~~~~~~~~~~~~~~~~^^^^^^^^^^^^^^^^^^^^^^^^^^^^^^^^^^^
  File "/home/ubuntu/.local/lib/python3.13/site-packages/django/db/models/sql/compiler.py", line 74, in setup_query
    self.select, self.klass_info, self.annotation_col_map = self.get_select(
                                                            ~~~~~~~~~~~~~~~^
        with_col_aliases=with_col_aliases,
        ^^^^^^^^^^^^^^^^^^^^^^^^^^^^^^^^^^
    )
    ^
  File "/home/ubuntu/.local/lib/python3.13/site-packages/django/db/models/sql/compiler.py", line 299, in get_select
    related_klass_infos = self.get_related_selections(select, select_mask)
  File "/home/ubuntu/.local/lib/python3.13/site-packages/django/db/models/sql/compiler.py", line 1396, in get_related_selections
    raise FieldError(
    ...<6 lines>...
    )
django.core.exceptions.FieldError: Invalid field name(s) given in select_related: 'cliente'. Choices are: usuario, plato
ERROR 2025-08-01 10:08:20,007 log 5854 140624463560960 Internal Server Error: /main/
Traceback (most recent call last):
  File "/home/ubuntu/.local/lib/python3.13/site-packages/django/core/handlers/exception.py", line 55, in inner
    response = get_response(request)
  File "/home/ubuntu/.local/lib/python3.13/site-packages/django/core/handlers/base.py", line 197, in _get_response
    response = wrapped_callback(request, *callback_args, **callback_kwargs)
  File "/home/ubuntu/.local/lib/python3.13/site-packages/django/contrib/auth/decorators.py", line 59, in _view_wrapper
    return view_func(request, *args, **kwargs)
  File "/workspace/myapp/views.py", line 155, in main
    return render(request, 'main.html', {
        'dias_semana': dias_semana,
    ...<6 lines>...
        'grupos': grupos,
    })
  File "/home/ubuntu/.local/lib/python3.13/site-packages/django/shortcuts.py", line 25, in render
    content = loader.render_to_string(template_name, context, request, using=using)
  File "/home/ubuntu/.local/lib/python3.13/site-packages/django/template/loader.py", line 62, in render_to_string
    return template.render(context, request)
           ~~~~~~~~~~~~~~~^^^^^^^^^^^^^^^^^^
  File "/home/ubuntu/.local/lib/python3.13/site-packages/django/template/backends/django.py", line 107, in render
    return self.template.render(context)
           ~~~~~~~~~~~~~~~~~~~~^^^^^^^^^
  File "/home/ubuntu/.local/lib/python3.13/site-packages/django/template/base.py", line 171, in render
    return self._render(context)
           ~~~~~~~~~~~~^^^^^^^^^
  File "/home/ubuntu/.local/lib/python3.13/site-packages/django/test/utils.py", line 114, in instrumented_test_render
    return self.nodelist.render(context)
           ~~~~~~~~~~~~~~~~~~~~^^^^^^^^^
  File "/home/ubuntu/.local/lib/python3.13/site-packages/django/template/base.py", line 1016, in render
    return SafeString("".join([node.render_annotated(context) for node in self]))
                               ~~~~~~~~~~~~~~~~~~~~~^^^^^^^^^
  File "/home/ubuntu/.local/lib/python3.13/site-packages/django/template/base.py", line 977, in render_annotated
    return self.render(context)
           ~~~~~~~~~~~^^^^^^^^^
  File "/home/ubuntu/.local/lib/python3.13/site-packages/django/template/base.py", line 1075, in render
    output = self.filter_expression.resolve(context)
  File "/home/ubuntu/.local/lib/python3.13/site-packages/django/template/base.py", line 749, in resolve
    new_obj = func(obj, *arg_vals)
  File "/home/ubuntu/.local/lib/python3.13/site-packages/django/template/defaultfilters.py", line 632, in length
    return len(value)
  File "/home/ubuntu/.local/lib/python3.13/site-packages/django/db/models/query.py", line 366, in __len__
    self._fetch_all()
    ~~~~~~~~~~~~~~~^^
  File "/home/ubuntu/.local/lib/python3.13/site-packages/django/db/models/query.py", line 1945, in _fetch_all
    self._result_cache = list(self._iterable_class(self))
                         ~~~~^^^^^^^^^^^^^^^^^^^^^^^^^^^^
  File "/home/ubuntu/.local/lib/python3.13/site-packages/django/db/models/query.py", line 91, in __iter__
    results = compiler.execute_sql(
        chunked_fetch=self.chunked_fetch, chunk_size=self.chunk_size
    )
  File "/home/ubuntu/.local/lib/python3.13/site-packages/django/db/models/sql/compiler.py", line 1610, in execute_sql
    sql, params = self.as_sql()
                  ~~~~~~~~~~~^^
  File "/home/ubuntu/.local/lib/python3.13/site-packages/django/db/models/sql/compiler.py", line 766, in as_sql
    extra_select, order_by, group_by = self.pre_sql_setup(
                                       ~~~~~~~~~~~~~~~~~~^
        with_col_aliases=with_col_aliases or bool(combinator),
        ^^^^^^^^^^^^^^^^^^^^^^^^^^^^^^^^^^^^^^^^^^^^^^^^^^^^^^
    )
    ^
  File "/home/ubuntu/.local/lib/python3.13/site-packages/django/db/models/sql/compiler.py", line 85, in pre_sql_setup
    self.setup_query(with_col_aliases=with_col_aliases)
    ~~~~~~~~~~~~~~~~^^^^^^^^^^^^^^^^^^^^^^^^^^^^^^^^^^^
  File "/home/ubuntu/.local/lib/python3.13/site-packages/django/db/models/sql/compiler.py", line 74, in setup_query
    self.select, self.klass_info, self.annotation_col_map = self.get_select(
                                                            ~~~~~~~~~~~~~~~^
        with_col_aliases=with_col_aliases,
        ^^^^^^^^^^^^^^^^^^^^^^^^^^^^^^^^^^
    )
    ^
  File "/home/ubuntu/.local/lib/python3.13/site-packages/django/db/models/sql/compiler.py", line 299, in get_select
    related_klass_infos = self.get_related_selections(select, select_mask)
  File "/home/ubuntu/.local/lib/python3.13/site-packages/django/db/models/sql/compiler.py", line 1396, in get_related_selections
    raise FieldError(
    ...<6 lines>...
    )
django.core.exceptions.FieldError: Invalid field name(s) given in select_related: 'cliente'. Choices are: usuario, plato
INFO 2025-08-01 10:09:47,942 autoreload 6607 139690391392512 Watching for file changes with StatReloader
WARNING 2025-08-01 10:10:09,005 log 6607 139690079418048 Forbidden: /api/
INFO 2025-08-01 10:11:59,924 autoreload 7779 140693028237568 Watching for file changes with StatReloader
